Workbook

Sheet Model
A1: NVIDIA CORP
A2: Financial Model (values in $Ms)
B3: Q325 | C3: Q425 | D3: Q126 | E3: Q226 | F3: Q326 | G3: Q426 | H3: Q127 | I3: Q227 | J3: Q327 | K3: Q427 | L3: Q128 | M3: Q228 | N3: Q328 | O3: Q428 | P3: Q129 | Q3: Q229 | R3: Q329 | S3: Q429
A4: Revenue | B4: 35082 | C4: 39331 | D4: 44062 | E4: 46743 | F4: 57006 | G4: 68127 | H4: 81615 | I4: 96221 | J4: =IF(Drivers!J15<>0,Drivers!J15,F4*(1+0.4000)) | K4: =IF(Drivers!K15<>0,Drivers!K15,G4*(1+0.3970)) | L4: =IF(Drivers!L15<>0,Drivers!L15,H4*(1+0.3884)) | M4: =IF(Drivers!M15<>0,Drivers!M15,I4*(1+0.3749)) | N4: =IF(Drivers!N15<>0,Drivers!N15,J4*(1+0.3571)) | O4: =IF(Drivers!O15<>0,Drivers!O15,K4*(1+0.3358)) | P4: =IF(Drivers!P15<>0,Drivers!P15,L4*(1+0.3114)) | Q4: =IF(Drivers!Q15<>0,Drivers!Q15,M4*(1+0.2848)) | R4: =IF(Drivers!R15<>0,Drivers!R15,N4*(1+0.2565)) | S4: =IF(Drivers!S15<>0,Drivers!S15,O4*(1+0.2273))
A5: COGS | B5: 8926 | C5: 10608 | D5: 17394 | E5: 12890 | F5: 15157 | G5: 17034 | H5: 20458 | I5: 24079 | J5: =J4*0.2600 | K5: =K4*0.2593 | L5: =L4*0.2593 | M5: =M4*0.2593 | N5: =N4*0.2593 | O5: =O4*0.2593 | P5: =P4*0.2593 | Q5: =Q4*0.2593 | R5: =R4*0.2593 | S5: =S4*0.2593
A6: Gross Profit | B6: =B4-B5 | C6: =C4-C5 | D6: =D4-D5 | E6: =E4-E5 | F6: =F4-F5 | G6: =G4-G5 | H6: =H4-H5 | I6: =I4-I5 | ... S6: =S4-S5
A7: S&M
A8: R&D | B8: 3390 | C8: 3714 | D8: 3989 | E8: 4291 | F8: 4705 | G8: 5512 | H8: 6321 | I8: 7054 | J8: =J4*0.0801 | K8: =K4*0.0801 | L8: =L4*0.0801 | M8: =M4*0.0801 | N8: =N4*0.0801 | O8: =O4*0.0801 | P8: =P4*0.0801 | Q8: =Q4*0.0801 | ... S8: =S4*0.0801
A9: G&A | B9: 897 | C9: 975 | D9: 1041 | E9: 1122 | F9: 1134 | G9: 1282 | H9: 1300 | I9: 1354 | J9: =J4*0.0175 | K9: =K4*0.0175 | L9: =L4*0.0175 | M9: =M4*0.0175 | N9: =N4*0.0175 | O9: =O4*0.0175 | P9: =P4*0.0175 | Q9: =Q4*0.0175 | ... S9: =S4*0.0175
A10: Operating Expenses | B10: =B7+B8+B9 | C10: =C7+C8+C9 | D10: =D7+D8+D9 | E10: =E7+E8+E9 | F10: =F7+F8+F9 | G10: =G7+G8+G9 | H10: =H7+H8+H9 | I10: =I7+I8+I9 | ... S10: =S7+S8+S9
A11: Operating Income | B11: =B6-B10 | C11: =C6-C10 | D11: =D6-D10 | E11: =E6-E10 | F11: =F6-F10 | G11: =G6-G10 | H11: =H6-H10 | I11: =I6-I10 | ... S11: =S6-S10
A12: Interest Income | B12: 447 | C12: 1183 | D12: 272 | E12: 2766 | F12: 1926 | G12: 6099 | H12: 16367 | I12: 7773 | J12: =J4*0.1012 | K12: =K4*0.1012 | L12: =L4*0.1012 | M12: =M4*0.1012 | N12: =N4*0.1012 | O12: =O4*0.1012 | P12: =P4*0.1012 | Q12: =Q4*0.1012 | ... S12: =S4*0.1012
A13: Pretax Income | B13: 22316 | C13: 25217 | D13: 21910 | E13: 31206 | F13: 37936 | G13: 50398 | H13: 69903 | I13: 71507 | J13: =J11+J12 | K13: =K11+K12 | L13: =L11+L12 | M13: =M11+M12 | N13: =N11+N12 | O13: =O11+O12 | P13: =P11+P12 | Q13: =Q11+Q12 | ... S13: =S11+S12
A14: Taxes | B14: 3007 | C14: 3126 | D14: 3135 | E14: 4784 | F14: 6026 | G14: 7438 | H14: 11582 | I14: 11819 | J14: =J13*0.1594 | K14: =K13*0.1594 | L14: =L13*0.1594 | M14: =M13*0.1594 | N14: =N13*0.1594 | O14: =O13*0.1594 | P14: =P13*0.1594 | Q14: =Q13*0.1594 | ... S14: =S13*0.1594
A15: Net Income | B15: 19309 | C15: 22091 | D15: 18775 | E15: 26422 | F15: 31910 | G15: 42960 | H15: 58321 | I15: 59688 | J15: =J13-J14 | K15: =K13-K14 | L15: =L13-L14 | M15: =M13-M14 | N15: =N13-N14 | O15: =O13-O14 | P15: =P13-P14 | Q15: =Q13-Q14 | ... S15: =S13-S14
A16: EPS | B16: 0.78 | D16: 0.76 | E16: 1.08 | F16: 1.3 | H16: 2.39 | I16: 2.46 | J16: =IF(J17<>0,J15/J17,"") | K16: =IF(K17<>0,K15/K17,"") | L16: =IF(L17<>0,L15/L17,"") | M16: =IF(M17<>0,M15/M17,"") | N16: =IF(N17<>0,N15/N17,"") | O16: =IF(O17<>0,O15/O17,"") | P16: =IF(P17<>0,P15/P17,"") | Q16: =IF(Q17<>0,Q15/Q17,"") | ... S16: =IF(S17<>0,S15/S17,"")
A17: Shares | B17: 24774 | D17: 24611 | E17: 24532 | F17: 24483 | H17: 24391 | I17: 24285 | J17: =24285.0-(J15*0.9*0.55/230.36) | K17: =J17-(K15*0.9*0.55/230.36) | L17: =K17-(L15*0.9*0.55/230.36) | M17: =L17-(M15*0.9*0.55/230.36) | N17: =M17-(N15*0.9*0.55/230.36) | O17: =N17-(O15*0.9*0.55/230.36) | P17: =O17-(P15*0.9*0.55/230.36) | Q17: =P17-(Q15*0.9*0.55/230.36) | R17: =Q17-(R15*0.9*0.55/230.36) | S17: =R17-(S15*0.9*0.55/230.36)
A19: Revenue y/y | F19: =F4/B4-1 | G19: =G4/C4-1 | H19: =H4/D4-1 | I19: =I4/E4-1 | J19: =J4/F4-1 | K19: =K4/G4-1 | L19: =L4/H4-1 | M19: =M4/I4-1 | ... S19: =S4/O4-1
A20: Gross Margin | B20: =IF(B4<>0,B6/B4,"") | C20: =IF(C4<>0,C6/C4,"") | D20: =IF(D4<>0,D6/D4,"") | E20: =IF(E4<>0,E6/E4,"") | F20: =IF(F4<>0,F6/F4,"") | G20: =IF(G4<>0,G6/G4,"") | H20: =IF(H4<>0,H6/H4,"") | I20: =IF(I4<>0,I6/I4,"") | ... S20: =IF(S4<>0,S6/S4,"")
A22: CFFO | B22: 17627 | C22: 16629 | D22: 27414 | E22: 15365 | F22: 23751 | G22: 36188 | H22: 50344 | I22: 24077 | J22: =J4*0.4537 | K22: =K4*0.4537 | L22: =L4*0.4537 | M22: =M4*0.4537 | N22: =N4*0.4537 | O22: =O4*0.4537 | P22: =P4*0.4537 | Q22: =Q4*0.4537 | ... S22: =S4*0.4537
A23: CX | B23: 813 | C23: 1077 | D23: 1227 | E23: 1895 | F23: 1636 | G23: 1284 | H23: 1757 | I23: 2677 | J23: =J4*0.0242 | K23: =K4*0.0242 | L23: =L4*0.0242 | M23: =M4*0.0242 | N23: =N4*0.0242 | O23: =O4*0.0242 | P23: =P4*0.0242 | Q23: =Q4*0.0242 | ... S23: =S4*0.0242
A24: FCF | B24: =B22-B23 | C24: =C22-C23 | D24: =D22-D23 | E24: =E22-E23 | F24: =F22-F23 | G24: =G22-G23 | H24: =H22-H23 | I24: =I22-I23 | ... S24: =S22-S23
A25: CFFO margin | B25: =IF(B4<>0,B22/B4,"") | C25: =IF(C4<>0,C22/C4,"") | D25: =IF(D4<>0,D22/D4,"") | E25: =IF(E4<>0,E22/E4,"") | F25: =IF(F4<>0,F22/F4,"") | G25: =IF(G4<>0,G22/G4,"") | H25: =IF(H4<>0,H22/H4,"") | I25: =IF(I4<>0,I22/I4,"") | ... S25: =IF(S4<>0,S22/S4,"")
A27: Cash | B27: 9107 | C27: 8589 | D27: 15234 | E27: 11639 | F27: 11486 | G27: 10605 | H27: 13237 | I27: 22443
A28: AR | B28: 17693 | C28: 23065 | D28: 22132 | E28: 27808 | F28: 33391 | G28: 38466 | H28: 40710 | I28: 63059
A29: Prepaids | B29: 3806 | C29: 3771 | D29: 2779 | E29: 2658 | F29: 2709 | G29: 3180 | H29: 3916 | I29: 3409
A30: PP&E | B30: 5343 | C30: 6283 | D30: 7136 | E30: 9141 | F30: 9780 | G30: 10383 | H30: 12403 | I30: 14285
A31: Goodwill | B31: 4724 | C31: 5188 | D31: 5498 | E31: 5755 | F31: 6261 | G31: 20832 | H31: 20894 | I31: 21125
A32: ONCA | B32: =B33-B27-B28-B29-B30-B31 | C32: =C33-C27-C28-C29-C30-C31 | D32: =D33-D27-D28-D29-D30-D31 | E32: =E33-E27-E28-E29-E30-E31 | F32: =F33-F27-F28-F29-F30-F31 | G32: =G33-G27-G28-G29-G30-G31 | H32: =H33-H27-H28-H29-H30-H31 | I32: =I33-I27-I28-I29-I30-I31
A33: Assets | B33: 96013 | C33: 111601 | D33: 125254 | E33: 140740 | F33: 161148 | G33: 206803 | H33: 259474 | I33: 320272
A35: AP | B35: 5353 | C35: 6310 | D35: 7331 | E35: 9064 | F35: 8624 | G35: 9812 | H35: 13097 | I35: 15059
A36: AL | B36: 11126 | C36: 11737 | D36: 19211 | E36: 15193 | F36: 16452 | G36: 21352 | H36: 29787 | I36: 26960
A37: DR | B37: 752 | C37: 837 | D37: 1074 | E37: 980 | F37: 1248 | G37: 1379 | H37: 1714 | I37: 4616
A38: Debt | B38: 8462 | C38: 8463 | D38: 8464 | E38: 8466 | F38: 8467 | G38: 8468 | H38: 8470 | I38: 33366
A39: ONCL | B39: =30114.0-B35-B36-B37-B38 | C39: =32274.0-C35-C36-C37-C38 | D39: =41411.0-D35-D36-D37-D38 | E39: =40609.0-E35-E36-E37-E38 | F39: =42251.0-F35-F36-F37-F38 | G39: =49510.0-G35-G36-G37-G38 | H39: =64000.0-H35-H36-H37-H38 | I39: =91288.0-I35-I36-I37-I38
A40: SE | B40: 65899 | C40: 79327 | D40: 83843 | E40: 100131 | F40: 118897 | G40: 157293 | H40: 195474 | I40: 228984
A41: L+SE | B41: =B35+B36+B37+B38+B39+B40 | C41: =C35+C36+C37+C38+C39+C40 | D41: =D35+D36+D37+D38+D39+D40 | E41: =E35+E36+E37+E38+E39+E40 | F41: =F35+F36+F37+F38+F39+F40 | G41: =G35+G36+G37+G38+G39+G40 | H41: =H35+H36+H37+H38+H39+H40 | I41: =I35+I36+I37+I38+I39+I40
A43: ANNUAL SUMMARY ($M)
B44: FY2026 | C44: FY2027 | D44: FY2028 | E44: FY2029
A45: Revenue | B45: =D4+E4+F4+G4 | C45: =H4+I4+J4+K4 | D45: =L4+M4+N4+O4 | E45: =P4+Q4+R4+S4
...

Sheet Drivers
A1: NVIDIA CORP - Revenue Drivers
A2: Input quarterly segment estimates in yellow cells ($Ms). Q4 columns show annual 10-K totals as reference. | Estimates: Q2 FY27 8-K: Q3 guide $108.0B +/-2%. Segments re-cut to the FY27 customer-type taxonomy; split held at the Q2 FY27 ACTUAL mix rather than extrapolating the 2-quarter AICIE share drift (too thin to trend).
B3: Q325 | C3: Q425 (FY) | D3: Q126 | E3: Q226 | F3: Q326 | G3: Q426 (FY) | H3: Q127 | I3: Q227 | J3: Q327 | K3: Q427 | L3: Q128 | M3: Q228 | N3: Q328 | O3: Q428 | P3: Q129 | Q3: Q229 | R3: Q329 | S3: Q429 | T3: FY2027E | U3: FY2028E | V3: FY2029E
A4: Hyperscale | D4: 17599 | E4: 24168 | H4: 37869 | I4: 48710 | J4: 54673 | K4: 60960 | L4: 63710 | M4: 66898 | N4: 69569 | O4: 72348 | T4: =H4+I4+J4+K4 | U4: =L4+M4+N4+O4 | V4: =P4+Q4+R4+S4
A5: AI Clouds, Industrial, & Enterprise | D5: 21513 | E5: 16928 | H5: 37377 | I5: 40313 | J5: 45248 | K5: 50451 | L5: 52727 | M5: 55366 | N5: 57576 | O5: 59876 | T5: =H5+I5+J5+K5 | U5: =L5+M5+N5+O5 | V5: =P5+Q5+R5+S5
A6: Compute | B6: 27644 | C6: 102196 | F6: 43028 | G6: 162361 | T6: =H6+I6+J6+K6 | U6: =L6+M6+N6+O6 | V6: =P6+Q6+R6+S6
A7: Networking | B7: 3127 | C7: 12990 | F7: 8187 | G7: 31376 | T7: =H7+I7+J7+K7 | U7: =L7+M7+N7+O7 | V7: =P7+Q7+R7+S7
A8: Data Center | B8: =B4+B5+B6+B7 | C8: =C4+C5+C6+C7 | D8: =D4+D5+D6+D7 | E8: =E4+E5+E6+E7 | F8: =F4+F5+F6+F7 | G8: =G4+G5+G6+G7 | H8: =H4+H5+H6+H7 | I8: =I4+I5+I6+I7 | ... S8: =S4+S5+S6+S7 | T8: =H8+I8+J8+K8 | U8: =L8+M8+N8+O8 | V8: =P8+Q8+R8+S8
A9: Edge Computing | D9: 4950 | E9: 5647 | H9: 6369 | I9: 7198 | J9: 8079 | K9: 9008 | L9: 9415 | M9: 9886 | N9: 10280 | O9: 10691 | T9: =H9+I9+J9+K9 | U9: =L9+M9+N9+O9 | V9: =P9+Q9+R9+S9
A10: Gaming | B10: 3279 | C10: 11350 | F10: 4265 | G10: 16042 | T10: =H10+I10+J10+K10 | U10: =L10+M10+N10+O10 | V10: =P10+Q10+R10+S10
A11: Professional Visualization | B11: 486 | C11: 1878 | F11: 760 | G11: 3191 | T11: =H11+I11+J11+K11 | U11: =L11+M11+N11+O11 | V11: =P11+Q11+R11+S11
A12: Automotive | B12: 449 | C12: 1694 | F12: 592 | G12: 2349 | T12: =H12+I12+J12+K12 | U12: =L12+M12+N12+O12 | V12: =P12+Q12+R12+S12
A13: OEM and Other | B13: 97 | C13: 389 | F13: 174 | G13: 619 | T13: =H13+I13+J13+K13 | U13: =L13+M13+N13+O13 | V13: =P13+Q13+R13+S13
T14: =H14+I14+J14+K14 | U14: =L14+M14+N14+O14 | V14: =P14+Q14+R14+S14
A15: Total Revenue (Driver-Based) | B15: =B8+B9+B10+B11+B12+B13 | C15: =C8+C9+C10+C11+C12+C13 | D15: =D8+D9+D10+D11+D12+D13 | E15: =E8+E9+E10+E11+E12+E13 | F15: =F8+F9+F10+F11+F12+F13 | G15: =G8+G9+G10+G11+G12+G13 | H15: =H8+H9+H10+H11+H12+H13 | I15: =I8+I9+I10+I11+I12+I13 | ... S15: =S8+S9+S10+S11+S12+S13 | T15: =H15+I15+J15+K15 | U15: =L15+M15+N15+O15 | V15: =P15+Q15+R15+S15

Sheet Scenarios
A1: Scenario Manager - NVIDIA CORP (NVDA)
A2: Edit yellow cells to override Bear/Base/Bull segment revenue ($M). Changes persist across refresh.
A4: SEGMENT REVENUE BY SCENARIO ($M)
A5: Segment | B5: FY27E (2Q) Bear | C5: FY27E (2Q) Base | D5: FY27E (2Q) Bull | E5: FY28E Bear | F5: FY28E Base | G5: FY28E Bull | H5: FY29E Bear | I5: FY29E Base | J5: FY29E Bull
A6: Hyperscale | E6: 172263.9 | F6: 272525 | G6: 372786.1
A7: AI Clouds, Industrial, & Enterprise | E7: 134145.8 | F7: 225545 | G7: 316944.2
A8: Compute
A9: Networking
A10: Data Center | B10: =B6+B7+B8+B9 | C10: =C6+C7+C8+C9 | D10: =D6+D7+D8+D9 | E10: =E6+E7+E8+E9 | F10: =F6+F7+F8+F9 | G10: =G6+G7+G8+G9 | H10: =H6+H7+H8+H9 | I10: =I6+I7+I8+I9 | J10: =J6+J7+J8+J9
A11: Edge Computing | E11: 36570.7 | F11: 40272 | G11: 43973.3
A12: Gaming
A13: Professional Visualization
A14: Automotive
A15: OEM and Other
A17: TOTAL REVENUE | B17: =B10+B11+B12+B13+B14+B15 | C17: =C10+C11+C12+C13+C14+C15 | D17: =D10+D11+D12+D13+D14+D15 | E17: =E10+E11+E12+E13+E14+E15 | F17: =F10+F11+F12+F13+F14+F15 | G17: =G10+G11+G12+G13+G14+G15 | H17: =H10+H11+H12+H13+H14+H15 | I17: =I10+I11+I12+I13+I14+I15 | J17: =J10+J11+J12+J13+J14+J15
A19: SCENARIO NARRATIVES
A20: Bear thesis:
A21: Bull thesis:
A24: 1. Yellow cells = your overrides for each scenario's segment revenue
A25: 2. Defaults from drivers section (Base) and segment volatility (Bear/Bull)
A26: 3. These values flow into DCF Bear/Base/Bull scenarios on next refresh

Sheet DCF
A1: DCF Valuation — NVIDIA CORP (NVDA)
A3: ASSUMPTIONS
A4: WACC | B4: 0.11465101
A5: Terminal Growth Rate | B5: 0.035
A6: Tax Rate | B6: 0.16046121
A7: Operating Margin (TTM) | B7: 0.65214263
A8: CapEx % of Revenue | B8: 0.02427311
A9: Maintenance CapEx % | B9: 0.018204833
A10: D&A % of Revenue | B10: 0.012169562
A11: NWC % of Revenue | B11: 0.065462143
A12: SBC % of Revenue | B12: 0.023900135
A13: Net Dilution Rate (SBC - Buybacks) | B13: -0.0086425126
A15: WACC BUILD
A16: Risk-Free Rate (Rf) | B16: 0.0478
A17: Equity Risk Premium (ERP) | B17: 0.0414
A18: Raw Beta | B18: 1.887
A19: Blume-Adjusted Beta (Own) | B19: 1.5913333
A20: Peer Blume Beta | B20: 1.6604647
A21: Blended Beta | B21: 1.625899
A22: Cost of Equity (Ke = Rf + β×ERP) | B22: 0.11511222
A23: Pre-Tax Cost of Debt | B23: 0.0478
A24: After-Tax Cost of Debt | B24: 0.037762
A25: Equity Weight (E/V) | B25: 0.99403739
A26: Debt Weight (D/V) | B26: 0.0059626131
A27: → WACC = (E/V)×Ke + (D/V)×Kd×(1-t) | B27: 0.11465101
A28: Beta: | B28: Peer-blended (curated)
A31: Revenue Growth Rates:
A32: Year 1 | B32: 0.3409
A33: Year 2 | B33: 0.3251
A34: Year 3 | B34: 0.2499
A35: Year 4 | B35: 0.1102
A36: Year 5 | B36: 0.035
A38: TTM FINANCIALS ($M)
A39: Revenue | B39: 302969
A40: Operating Income | B40: 197579
A41: Net Income | B41: 192879
A42: Stock-Based Comp | B42: 7241
A43: Share Buybacks | B43: 55315
A44: CFFO | B44: 134360
A45: CapEx | B45: 7354
...

Sheet Reverse DCF
A1: Reverse DCF — NVIDIA CORP (NVDA)
A2: What annual FCF growth rate is the market pricing in at today's stock price?
A4: RESULT
A5: Implied Annual FCF Growth | B5: 0.29987793
A6: Current Stock Price | B6: 230.36
A8: HISTORICAL REVENUE GROWTH (CAGR)
A9: 1yr Avg Revenue Growth | B9: 0.83375298
A10: 3yr Avg Revenue Growth | B10: 1.1007173
A11: 5yr Avg Revenue Growth | B11: 0.69123016
A12: ✓ Market implies 30% growth vs 110% historical — conservative pricing
A14: The market expects strong growth (30%/yr). Reasonable for high-growth tech but watch for deceleration.
A16: WHAT MUST BE TRUE FOR $230 TO BE FAIR VALUE
A17: Market price requires AT LEAST ONE of these (not all three) — each holds other base-case operational assumptions constant.
A18: Required TTM Revenue (starting point) | B18: 411767.12 | C18: vs base $302,969M (Δ +36%)
A19: Required Operating Margin (held constant) | B19: out of search range
A20: Required Terminal Growth Rate | B20: 0.060208902 | C20: vs base 3.5% (Δ +2.5pp)
A22: ASSUMPTIONS USED | C22: (linked to DCF tab)
A23: WACC | B23: =DCF!B4
A24: Terminal Growth Rate | B24: =DCF!B5
A25: Tax Rate | B25: =DCF!B6
A26: Operating Margin | B26: =DCF!B7
A27: CapEx % of Revenue | B27: =DCF!B8
A28: D&A % of Revenue | B28: =DCF!B10
A30: SENSITIVITY TABLE
A31: Implied FCF Growth Rate for different WACC / Terminal Growth combos
A32: WACC ↓ / TGR → | B32: 0.01 | C32: 0.015 | D32: 0.02 | E32: 0.025 | F32: 0.03 | G32: 0.035 | H32: 0.04
A33: 0.0847 | B33: 0.25561523 | C33: 0.23989258 | D33: 0.22314453 | E33: 0.20537109 | F33: 0.18605957 | G33: 0.16520996 | H33: 0.14248047
A34: 0.0947 | B34: 0.29458008 | C34: 0.28039551 | D34: 0.26552734 | E34: 0.24963379 | F34: 0.23271484 | G34: 0.21459961 | H34: 0.19528809
A35: 0.1047 | B35: 0.33081055 | C35: 0.31799316 | D35: 0.30449219 | E35: 0.29013672 | F35: 0.27509766 | G35: 0.2592041 | H35: 0.24228516
A36: 0.1147 | B36: 0.36533203 | C36: 0.35336914 | D36: 0.34106445 | E36: 0.32807617 | F36: 0.3144043 | G36: 0.30004883 | H36: 0.28500977
A37: 0.1247 | B37: 0.39797363 | C37: 0.38703613 | D37: 0.37558594 | E37: 0.36362305 | F37: 0.35131836 | G37: 0.33815918 | H37: 0.3244873
A38: 0.1347 | B38: 0.42941895 | C38: 0.41916504 | D38: 0.40856934 | E38: 0.39746094 | F38: 0.38601074 | G38: 0.37387695 | H38: 0.36140137
A39: 0.1447 | B39: 0.45966797 | C39: 0.45009766 | D39: 0.44018555 | E39: 0.42993164 | F39: 0.41899414 | G39: 0.40805664 | H39: 0.39643555
A42: GROWTH × MARGIN GRID (Implied Price)
A43: Each cell = implied share price for that (revenue CAGR, op margin) combo. Find the cell closest to current price; that pair is what the market is pricing.
A44: Op Margin ↓ / Rev CAGR → | B44: 0.19987793 | C44: 0.24987793 | D44: 0.29987793 | E44: 0.34987793 | F44: 0.39987793
A45: 0.55214263 | B45: 133.20852 | C45: 160.43068 | D45: 192.13136 | E45: 228.85395 | F45: 271.18454
A46: 0.60214263 | B46: 146.32824 | C46: 176.23419 | D46: 211.0599 | E46: 251.40229 | F46: 297.90516
A47: 0.65214263 | B47: 159.44797 | C47: 192.0377 | D47: 229.98844 | E47: 273.95062 | F47: 324.62578
A48: 0.70214263 | B48: 172.56769 | C48: 207.84121 | D48: 248.91698 | E48: 296.49896 | F48: 351.3464
...

Sheet Monte Carlo
A1: Monte Carlo DCF Simulation - NVIDIA CORP (NVDA)
A3: METHODOLOGY
A4: 1,000 iterations (1,000 valid)
A5: Operating variables: correlated blend between Bear/Base/Bull scenarios
A6: WACC: Normal(11.5%, 1.5% std) | TGR: Triangular(2.0%, 3.5%, 5.0%)
A7: Revenue exec shock: ±15% σ (multiplicative, ±2σ clipped) | Margin exec shock: ±3.0pp σ (additive, ±2σ clipped)
A8: Seed: 42 (deterministic — same inputs produce same output)
A10: SUMMARY STATISTICS
A11: Mean Implied Price | B11: 177.50097
A12: Median Implied Price (50th pctl) | B12: 167.88713
A13: Standard Deviation | B13: 51.841619
A15: PERCENTILE TABLE
A16: Percentile | B16: Implied Price | C16: vs Current
A17: 5th | B17: 111.64473 | C17: -0.5153467
A18: 25th | B18: 142.82369 | C18: -0.37999787
A19: 50th | B19: 167.88713 | C19: -0.27119668
A20: 75th | B20: 200.27825 | C20: -0.13058581
A21: 95th | B21: 272.87296 | C21: 0.1845501
A23: PROBABILITY ANALYSIS
A24: Current Share Price | B24: 230.36
A25: P(Undervalued) | B25: 0.135 | C25: Majority of scenarios imply downside
A27: SCENARIO ANCHORS
A28: Bear Implied | B28: 119.4138
A29: Base Implied | B29: 167.20335
A30: Bull Implied | B30: 205.07299
A32: PRICE DISTRIBUTION
A33: $79-$102 | B33: ███ | C33: (22)
A34: $102-$125 | B34: ████████████████ | C34: (98)
A35: $125-$149 | B35: ██████████████████████████████ | C35: (184)
A36: $149-$172 | B36: ████████████████████████████████████████ | C36: (245)
A37: $172-$196 | B37: ███████████████████████████ | C37: (170)
A38: $196-$219 | B38: ██████████████████ | C38: (112)
A39: $219-$243 | B39: █████████ | C39: (61)
A40: $243-$266 | B40: ███████ | C40: (44)
A41: $266-$289 | B41: █████ | C41: (34)
A42: $289-$313 | B42: █ | C42: (12)
A43: $313-$336 | C43: (6)
A44: $336-$360 | C44: (5)
A45: $360-$383 | C45: (2)
A46: $383-$407 | C46: (1)
...

Sheet Comps
A1: Comparable Company Analysis
A3: Ticker | B3: Company | C3: Market Cap ($B) | D3: Price | E3: Trailing P/E | F3: Forward P/E | G3: EV/EBITDA | H3: P/S | I3: EV/Rev | J3: P/B | K3: PEG | L3: Rev Growth | M3: Gross Margin | N3: Op Margin | O3: Net Margin | P3: ROE | Q3: Div Yield
A4: AVGO | B4: Broadcom Inc. | C4: 1702.7141 | D4: 357.895 | E4: 45.475857 | F4: 45.475857 | G4: 33.447 | H4: 19.10929 | I4: 19.541 | J4: 17.110245 | K4: 0.4 | L4: 0.855 | M4: 0.75515 | N4: 0.54307 | O4: 0.42944 | P4: 0.44245 | Q4: 0.0073
A5: TSM | B5: Taiwan Semiconductor Manufactur | C5: 2224.5307 | D5: 428.91 | E5: 31.841871 | F5: 31.841871 | G5: 4.858 | H5: 0.5009649 | I5: 3.466 | J5: 88.28834 | K5: 0.79 | L5: 0.36 | M5: 0.6423 | N5: 0.60344005 | O5: 0.49923 | P5: 0.39969003 | Q5: 0.0098
A6: AMD | B6: Advanced Micro Devices, Inc. | C6: 779.62111 | D6: 477.57 | E6: 116.19707 | F6: 116.19707 | G6: 80.609 | H6: 18.874739 | I6: 18.661 | J6: 11.594037 | K6: 0.48 | L6: 0.501 | M6: 0.55724 | N6: 0.1725 | O6: 0.15577 | P6: 0.10196
A7: MU | B7: Micron Technology, Inc. | C7: 1148.1298 | D7: 1016.59 | E7: 21.643389 | F7: 21.643389 | G7: 16.541 | H7: 12.718278 | I7: 12.501 | J7: 11.394834 | K7: 0.14 | L7: 3.457 | M7: 0.72569 | N7: 0.80370003 | O7: 0.55906 | P7: 0.66638 | Q7: 0.06
A8: Median | E8: 38.658864 | F8: 38.658864 | G8: 24.994 | H8: 15.796508 | I8: 15.581 | J8: 14.352141 | K8: 0.44 | L8: 0.678 | M8: 0.683995 | N8: 0.57325503 | O8: 0.464335 | P8: 0.42107002 | Q8: 0.0098

Sheet Multiples
A1: Multiple-Based Valuation — NVIDIA CORP (NVDA)
A2: Peers: AVGO, TSM, AMD, MU
A4: FORWARD METRICS ($M)
A5: NTM EPS (Trailing Margin) | B5: 12.29
A6: Normalized EPS (Mid-Cycle Avg Margin) | B6: 4.98
A7: NTM EBITDA (Projected OpInc + D&A) | B7: 313689.1
A8: NTM EBIT (Operating Income) | B8: 310002.1
A9: NTM Revenue (Projected) | B9: 454453.5
A10: TTM Free Cash Flow | B10: 127006
A11: FCF Yield (TTM FCF / EV) | B11: 0.02
A12: Shares Outstanding (M) | B12: 24285
A13: Cash | B13: 22443
A14: Debt | B14: 33366
A15: Book Value (Stockholders' Equity) | B15: 228984
A16: Book Value Per Share | B16: 9.43
... A21: P/E EPS Basis - Trailing EPS (peer fwd P/E gated to trailing) | B21: 7.94
A23: DUPONT ROE DECOMPOSITION
A24: Net Profit Margin (NI / Revenue) | B24: 0.6366
A25: Asset Turnover (Revenue / Assets) | B25: 0.946
A26: Equity Multiplier (Assets / Equity) | B26: 1.3987
A27: Return on Equity (ROE) | B27: 0.8423
A29: GEOGRAPHIC REVENUE SPLIT
A30: United States | B30: 0.6929 | C30: ████████████████████
A31: Taiwan | B31: 0.1961 | C31: █████
A32: China | B32: 0.0911 | C32: ██
A33: Other | B33: 0.0199
A35: US / International | B35: 69% / 31%
A37: CUSTOMER CONCENTRATION
A38: Status: CONCENTRATED
A39: 22% of total revenue
A40: 14% of total revenue
A42: For fiscal year 2026, sales to one direct customer represented 22% of total revenue and sales to another direct customer represented 14% of total revenue, all of which were primarily attributable to the Compute & Networking segment. 40 Table of Contents Concentration of Revenue We refer to customers who purchase products directly from NVIDIA as direct customers, such as AIBs, distributors, ODMs, OEMs, CSPs, AI model makers, and system integrators. Direct Customers – For fiscal year 2026, sale...
A44: VALUATION BY MULTIPLES
A45: Method | B45: Low Multiple | C45: Mid Multiple | D45: High Multiple | E45: Low Price | F45: Mid Price | G45: High Price
A46: Forward P/E | B46: 27.06559 | C46: 31.841871 | D46: 36.618152 | E46: =$B$21*B46 | F46: =$B$21*C46 | G46: =$B$21*D46
A47: EV/EBITDA | B47: 28.42995 | C47: 33.447 | D47: 38.46405 | E47: =IF($B$12<>0,($B$7*B47-$B$14+$B$13)/$B$12,0) | F47: =IF($B$12<>0,($B$7*C47-$B$14+$B$13)/$B$12,0) | G47: =IF($B$12<>0,($B$7*D47-$B$14+$B$13)/$B$12,0)
A48: EV/Revenue | B48: 15.86185 | C48: 18.661 | D48: 21.46015 | E48: =IF($B$12<>0,($B$9*B48-$B$14+$B$13)/$B$12,0) | F48: =IF($B$12<>0,($B$9*C48-$B$14+$B$13)/$B$12,0) | G48: =IF($B$12<>0,($B$9*D48-$B$14+$B$13)/$B$12,0)
A50: Current Market Price | B50: 230.36
A51: Premium / Discount to Mid
A52: Forward P/E | B52: =IF(B50<>0,F46/B50-1,0)
...

Sheet Hyperscaler
A1: Hyperscaler Capex Dependency — NVDA Leading Indicator
A2: Hyperscaler-driven NVDA DC rev = Σ (capex × AI%) × NVDA take rate. YoY gap vs actual NVDA DC revenue is a 1-2 quarter leading indicator.
A4: 1) AI% of Capex (per hyperscaler)
A5: Hyperscaler | B5: AI % | C5: Source | D5: Date | G5: Quote
A6: MSFT | B6: 0.7 | C6: Q3 FY26 earnings 8-K (Apr 29 2026) | G6: Q3 FY26 (period ending ); capex commentary tied to Azure AI infrastructure expansion. ~70% AI-attributable per mgmt commentary on
A7: META | B7: 0.8 | C7: Q1 CY26 earnings 8-K (Apr 29 2026) | G7: Q1 CY26 print; vast majority of 2026 capex growth tied to AI/servers per prior mgmt guidance. ~80% AI-attributable.
A8: GOOGL | B8: 0.65 | C8: Q1 CY26 earnings 8-K (Apr 29 2026) | G8: Q1 CY26 print; AI/TPU infrastructure ~65% of Alphabet capex; data center build-out + Trillium/TPU.
A9: AMZN | B9: 0.45 | C9: Q1 CY26 earnings 8-K (Apr 29 2026) | G9: Q1 CY26 print; AWS + AI share ~45% of total capex (balance is fulfillment / logistics infrastructure).
A10: ORCL | B10: 0.8 | C10: Q3 FY26 earnings 8-K (Mar 10 2026) | G10: Q3 FY26 print; OCI + Stargate capex heavily AI-weighted. ~80% AI-attributable.
A12: Yellow cells are editable.
A14: 2) Hyperscaler Capex TTM ($M)
A15: Ticker | B15: Prior TTM | C15: Current TTM | D15: YoY | E15: AI % | F15: AI Capex (TTM)
A16: MSFT | B16: 64551 | C16: 115948 | D16: 0.79622314 | E16: 0.7 | F16: 81163.6
A17: META | B17: 52162 | C17: 89325 | D17: 0.71245351 | E17: 0.8 | F17: 71460
A18: GOOGL | B18: 66980 | C18: 132402 | D18: 0.97673933 | E18: 0.65 | F18: 86061.3
A19: AMZN | B19: 107656 | C19: 173028 | D19: 0.60723044 | E19: 0.45 | F19: 77862.6
A20: ORCL | B20: 21215 | C20: 55663 | D20: 1.6237568 | E20: 0.8 | F20: 44530.4
A21: TOTAL | B21: 312564 | C21: 566366 | D21: 0.8120001 | E21: 0.63753456 | F21: 361077.9
A23: 3) NVDA DC Revenue Decomposition (TTM)
B24: Prior TTM ($M) | C24: Current TTM ($M) | D24: YoY
A25: Total hyperscaler capex | B25: 312564 | C25: 566366 | D25: 0.8120001
A26: × weighted AI% → AI capex pool | B26: 195869.5 | C26: 361077.9 | D26: 0.84346159
A28: NVDA take rate (share of AI capex going to NVDA GPUs) | C28: 0.4 | D28: (fixed)
A30: → Hyperscaler-driven NVDA DC rev | B30: 78347.8 | C30: 144431.16
A31: + Non-hyperscaler NVDA DC rev | B31: 36838.2 | C31: 133366.84 | D31: 2.6203408
A32: Total NVDA DC revenue (actual) | B32: 115186 | C32: 277798
A34: Hyperscaler dependency ratio | B34: 0.68018509 | C34: 0.51991433 | D34: -0.16027077
A36: 4) Leading Indicator — YoY Capex vs NVDA DC
A37: Hyperscaler AI capex growth (YoY) | B37: 0.84346159
A38: Leading indicator unavailable — need 8 quarters of capex data (have fewer). Will populate after next refresh.
A40: How to read: Hyperscaler capex → AI capex → NVDA GPU revenue is a 1-2 quarter leading indicator. Hyperscalers guide capex on earnings calls before NVDA ships the silicon. Track the YoY gap each quarter: a negative gap (hyperscalers spending faster than NVDA ships) is the first observable sign of a supply-constrained upswing. A persistently positive gap (NVDA outgrowing hyperscaler capex) means non-hyperscaler demand is carrying the growth.

Sheet Runway & Dilution
A1: Runway & Dilution — NVIDIA CORP
A2: Share discipline + cash runway ($Ms; shares in millions). Historical quarters only — raw parsed values, no forecasts.
B3: Q325 | C3: Q425 | D3: Q126 | E3: Q226 | F3: Q326 | G3: Q426 | H3: Q127 | I3: Q227
A4: Diluted Shares (M) | B4: 24774 | D4: 24611 | E4: 24532 | F4: 24483 | H4: 24391 | I4: 24285
A5: Share Dilution y/y | B5: -0.0067 | D5: -0.0112 | E5: -0.0127 | F5: -0.0117 | H5: -0.0089 | I5: -0.0101
A6: SBC ($M) | B6: 1252 | C6: 1321 | D6: 1474 | E6: 1625 | F6: 1654 | G6: 1633 | H6: 1928 | I6: 2026
A7: SBC % of Revenue | B7: 0.0357 | C7: 0.0336 | D7: 0.0335 | E7: 0.0348 | F7: 0.029 | G7: 0.024 | H7: 0.0236 | I7: 0.0211
A9: Cash ($M) | B9: 9107 | C9: 8589 | D9: 15234 | E9: 11639 | F9: 11486 | G9: 10605 | H9: 13237 | I9: 22443
A10: Quarterly FCF ($M) | B10: 16814 | C10: 15552 | D10: 26187 | E10: 13470 | F10: 22115 | G10: 34904 | H10: 48587 | I10: 21400
A12: RUNWAY
A13: TTM FCF ($M) | B13: 127006
A14: Runway | B14: Self-funding | C14: (TTM FCF positive — burn math not applicable)
A16: HOW TO READ: Share Dilution y/y compares the same fiscal quarter a year back (Q4 weighted
A17: averages can't be imputed, so some quarters may be blank). Dilution is NET — the diluted
A18: count already reflects buybacks. Audit flags net dilution: YELLOW > 4%/yr, RED > 8%/yr
A20: Quarterly FCF = CFFO - CX from raw filings. Runway = cash / average quarterly burn when
A21: TTM FCF is negative. Under ~8 quarters of runway, expect a raise — model the dilution.
